Traceback (most recent call last):
  File "/usr/local/lib/python3.11/site-packages/jupyter_cache/executors/utils.py", line 58, in single_nb_execution
    executenb(
  File "/usr/local/lib/python3.11/site-packages/nbclient/client.py", line 1204, in execute
    return NotebookClient(nb=nb, resources=resources, km=km, **kwargs).execute()
           ^^^^^^^^^^^^^^^^^^^^^^^^^^^^^^^^^^^^^^^^^^^^^^^^^^^^^^^^^^^^^^^^^^^^^
  File "/usr/local/lib/python3.11/site-packages/nbclient/util.py", line 84, in wrapped
    return just_run(coro(*args, **kwargs))
           ^^^^^^^^^^^^^^^^^^^^^^^^^^^^^^^
  File "/usr/local/lib/python3.11/site-packages/nbclient/util.py", line 62, in just_run
    return loop.run_until_complete(coro)
           ^^^^^^^^^^^^^^^^^^^^^^^^^^^^^
  File "/usr/local/Cellar/python@3.11/3.11.2_1/Frameworks/Python.framework/Versions/3.11/lib/python3.11/asyncio/base_events.py", line 653, in run_until_complete
    return future.result()
           ^^^^^^^^^^^^^^^
  File "/usr/local/lib/python3.11/site-packages/nbclient/client.py", line 663, in async_execute
    await self.async_execute_cell(
  File "/usr/local/lib/python3.11/site-packages/nbclient/client.py", line 965, in async_execute_cell
    await self._check_raise_for_error(cell, cell_index, exec_reply)
  File "/usr/local/lib/python3.11/site-packages/nbclient/client.py", line 862, in _check_raise_for_error
    raise CellExecutionError.from_cell_and_msg(cell, exec_reply_content)
nbclient.exceptions.CellExecutionError: An error occurred while executing the following cell:
------------------
start_scope()
from matplotlib.image import imread
img = (1-imread('brian.png'))[::-1, :, 0].T
num_samples, N = img.shape
ta = TimedArray(img, dt=1*ms) # 228
A = 1.5
tau = 2*ms
eqs = '''
dv/dt = (A*ta(t, i)-v)/tau+0.8*xi*tau**-0.5 : 1
'''
G = NeuronGroup(N, eqs, threshold='v>1', reset='v=0', method='euler')
M = SpikeMonitor(G)
run(num_samples*ms)
plot(M.t/ms, M.i, '.k', ms=3)
xlim(0, num_samples)
ylim(0, N)
xlabel('Time (ms)')
ylabel('Neuron index');
------------------

[0;31m---------------------------------------------------------------------------[0m
[0;31mFileNotFoundError[0m                         Traceback (most recent call last)
Cell [0;32mIn[16], line 3[0m
[1;32m      1[0m start_scope()
[1;32m      2[0m [38;5;28;01mfrom[39;00m [38;5;21;01mmatplotlib[39;00m[38;5;21;01m.[39;00m[38;5;21;01mimage[39;00m [38;5;28;01mimport[39;00m imread
[0;32m----> 3[0m img [38;5;241m=[39m ([38;5;241m1[39m[38;5;241m-[39m[43mimread[49m[43m([49m[38;5;124;43m'[39;49m[38;5;124;43mbrian.png[39;49m[38;5;124;43m'[39;49m[43m)[49m)[::[38;5;241m-[39m[38;5;241m1[39m, :, [38;5;241m0[39m][38;5;241m.[39mT
[1;32m      4[0m num_samples, N [38;5;241m=[39m img[38;5;241m.[39mshape
[1;32m      5[0m ta [38;5;241m=[39m TimedArray(img, dt[38;5;241m=[39m[38;5;241m1[39m[38;5;241m*[39mms) [38;5;66;03m# 228[39;00m

File [0;32m/usr/local/Cellar/graph-tool/2.46/libexec/lib/python3.11/site-packages/matplotlib/image.py:1541[0m, in [0;36mimread[0;34m(fname, format)[0m
[1;32m   1534[0m [38;5;28;01mif[39;00m [38;5;28misinstance[39m(fname, [38;5;28mstr[39m) [38;5;129;01mand[39;00m [38;5;28mlen[39m(parse[38;5;241m.[39murlparse(fname)[38;5;241m.[39mscheme) [38;5;241m>[39m [38;5;241m1[39m:
[1;32m   1535[0m     [38;5;66;03m# Pillow doesn't handle URLs directly.[39;00m
[1;32m   1536[0m     [38;5;28;01mraise[39;00m [38;5;167;01mValueError[39;00m(
[1;32m   1537[0m         [38;5;124m"[39m[38;5;124mPlease open the URL for reading and pass the [39m[38;5;124m"[39m
[1;32m   1538[0m         [38;5;124m"[39m[38;5;124mresult to Pillow, e.g. with [39m[38;5;124m"[39m
[1;32m   1539[0m         [38;5;124m"[39m[38;5;124m``np.array(PIL.Image.open(urllib.request.urlopen(url)))``.[39m[38;5;124m"[39m
[1;32m   1540[0m         )
[0;32m-> 1541[0m [38;5;28;01mwith[39;00m [43mimg_open[49m[43m([49m[43mfname[49m[43m)[49m [38;5;28;01mas[39;00m image:
[1;32m   1542[0m     [38;5;28;01mreturn[39;00m (_pil_png_to_float_array(image)
[1;32m   1543[0m             [38;5;28;01mif[39;00m [38;5;28misinstance[39m(image, PIL[38;5;241m.[39mPngImagePlugin[38;5;241m.[39mPngImageFile) [38;5;28;01melse[39;00m
[1;32m   1544[0m             pil_to_array(image))

File [0;32m/usr/local/lib/python3.11/site-packages/PIL/ImageFile.py:105[0m, in [0;36mImageFile.__init__[0;34m(self, fp, filename)[0m
[1;32m    101[0m [38;5;28mself[39m[38;5;241m.[39mdecodermaxblock [38;5;241m=[39m MAXBLOCK
[1;32m    103[0m [38;5;28;01mif[39;00m is_path(fp):
[1;32m    104[0m     [38;5;66;03m# filename[39;00m
[0;32m--> 105[0m     [38;5;28mself[39m[38;5;241m.[39mfp [38;5;241m=[39m [38;5;28;43mopen[39;49m[43m([49m[43mfp[49m[43m,[49m[43m [49m[38;5;124;43m"[39;49m[38;5;124;43mrb[39;49m[38;5;124;43m"[39;49m[43m)[49m
[1;32m    106[0m     [38;5;28mself[39m[38;5;241m.[39mfilename [38;5;241m=[39m fp
[1;32m    107[0m     [38;5;28mself[39m[38;5;241m.[39m_exclusive_fp [38;5;241m=[39m [38;5;28;01mTrue[39;00m

[0;31mFileNotFoundError[0m: [Errno 2] No such file or directory: 'brian.png'
FileNotFoundError: [Errno 2] No such file or directory: 'brian.png'

