Traceback (most recent call last):
  File "/Users/enaj/.virtualenvs/p39/lib/python3.9/site-packages/jupyter_cache/executors/utils.py", line 51, in single_nb_execution
    executenb(
  File "/Users/enaj/.virtualenvs/p39/lib/python3.9/site-packages/nbclient/client.py", line 1204, in execute
    return NotebookClient(nb=nb, resources=resources, km=km, **kwargs).execute()
  File "/Users/enaj/.virtualenvs/p39/lib/python3.9/site-packages/nbclient/util.py", line 84, in wrapped
    return just_run(coro(*args, **kwargs))
  File "/Users/enaj/.virtualenvs/p39/lib/python3.9/site-packages/nbclient/util.py", line 62, in just_run
    return loop.run_until_complete(coro)
  File "/usr/local/Cellar/python@3.9/3.9.16/Frameworks/Python.framework/Versions/3.9/lib/python3.9/asyncio/base_events.py", line 647, in run_until_complete
    return future.result()
  File "/Users/enaj/.virtualenvs/p39/lib/python3.9/site-packages/nbclient/client.py", line 663, in async_execute
    await self.async_execute_cell(
  File "/Users/enaj/.virtualenvs/p39/lib/python3.9/site-packages/nbclient/client.py", line 965, in async_execute_cell
    await self._check_raise_for_error(cell, cell_index, exec_reply)
  File "/Users/enaj/.virtualenvs/p39/lib/python3.9/site-packages/nbclient/client.py", line 862, in _check_raise_for_error
    raise CellExecutionError.from_cell_and_msg(cell, exec_reply_content)
nbclient.exceptions.CellExecutionError: An error occurred while executing the following cell:
------------------
from scipy import linalg

C_inverse = linalg.inv(C)
print(C_inverse)

## Your solution here
------------------

[0;31m---------------------------------------------------------------------------[0m
[0;31mNameError[0m                                 Traceback (most recent call last)
Input [0;32mIn [12][0m, in [0;36m<cell line: 3>[0;34m()[0m
[1;32m      1[0m [38;5;28;01mfrom[39;00m [38;5;21;01mscipy[39;00m [38;5;28;01mimport[39;00m linalg
[0;32m----> 3[0m C_inverse [38;5;241m=[39m linalg[38;5;241m.[39minv([43mC[49m)
[1;32m      4[0m [38;5;28mprint[39m(C_inverse)

[0;31mNameError[0m: name 'C' is not defined
NameError: name 'C' is not defined

